<mujoco model="right_shadow_hand">
  <compiler angle="radian" meshdir="assets" autolimits="true"/>

  <option cone="elliptic" impratio="10"/>

  <default>
    <default class="right_hand">
      <mesh scale="0.001 0.001 0.001"/>
      <joint axis="1 0 0" damping="0.05" armature="0.0002" frictionloss="0.01"/>
      <position forcerange="-1 1"/>

      <default class="wrist">
        <joint damping="0.5"/>
        <default class="wrist_y">
          <joint axis="0 1 0" range="-0.523599 0.174533"/>
          <position kp="10" ctrlrange="-0.523599 0.174533" forcerange="-10 10"/>
        </default>
        <default class="wrist_x">
          <joint range="-0.698132 0.488692"/>
          <position kp="8" ctrlrange="-0.698132 0.488692" forcerange="-5 5"/>
        </default>
      </default>

      <default class="thumb">
        <default class="thbase">
          <joint axis="0 0 -1" range="-1.0472 1.0472"/>
          <position kp="0.4" ctrlrange="-1.0472 1.0472" forcerange="-3 3"/>
        </default>
        <default class="thproximal">
          <joint range="0 1.22173"/>
          <position ctrlrange="0 1.22173" forcerange="-2 2"/>
        </default>
        <default class="thhub">
          <joint range="-0.20944 0.20944"/>
          <position kp="0.5" ctrlrange="-0.20944 0.20944"/>
        </default>
        <default class="thmiddle">
          <joint axis="0 -1 0" range="-0.698132 0.698132"/>
          <position kp="1.5" ctrlrange="-0.698132 0.698132"/>
        </default>
        <default class="thdistal">
          <joint range="-0.261799 1.5708"/>
          <position ctrlrange="-0.261799 1.5708"/>
        </default>
      </default>

      <default class="metacarpal">
        <joint axis="0.573576 0 0.819152" range="0 0.785398"/>
        <position ctrlrange="0 0.785398"/>
      </default>
      <default class="knuckle">
        <joint axis="0 -1 0" range="-0.349066 0.349066"/>
        <position ctrlrange="-0.349066 0.349066"/>
      </default>
      <default class="proximal">
        <joint range="-0.261799 1.5708"/>
        <position ctrlrange="-0.261799 1.5708"/>
      </default>
      <default class="middle_distal">
        <joint range="0 1.5708"/>
        <position kp="0.5" ctrlrange="0 3.1415"/>
      </default>

      <default class="plastic">
        <geom solimp="0.5 0.99 0.0001" solref="0.005 1"/>
        <default class="plastic_visual">
          <geom type="mesh" material="black" contype="0" conaffinity="0" group="2"/>
        </default>
        <default class="plastic_collision">
          <geom group="3"/>
        </default>
      </default>
    </default>
  </default>

  <asset>
    <material name="black" rgba="0.0117647 0.0117647 0.0117647 1" metallic="0" roughness="0.45" ior="1.35"
      clearcoat="0" clearcoatroughness="0" transmission="0" thickness="0"/>
    <material name="gray" rgba="0.8078431 0.8078431 0.8078431 1" metallic="1" roughness="0.24"/>
    <material name="metallic" rgba="0.9019608 0.9019608 0.9019608 1" metallic="1" roughness="0.18" clearcoat="0"/>

    <mesh class="right_hand" file="forearm_0.obj"/>
    <mesh class="right_hand" file="forearm_1.obj"/>
    <mesh class="right_hand" file="forearm_collision.obj"/>
    <mesh class="right_hand" file="wrist.obj"/>
    <mesh class="right_hand" file="palm.obj"/>
    <mesh class="right_hand" file="f_knuckle.obj"/>
    <mesh class="right_hand" file="f_proximal.obj"/>
    <mesh class="right_hand" file="f_middle.obj"/>
    <mesh class="right_hand" file="f_distal_pst.obj"/>
    <mesh class="right_hand" file="lf_metacarpal.obj"/>
    <mesh class="right_hand" file="th_proximal.obj"/>
    <mesh class="right_hand" file="th_middle.obj"/>
    <mesh class="right_hand" file="th_distal_pst.obj"/>
  </asset>

  <worldbody>
    <body name="rh_forearm" pos="0 0 0.075" childclass="right_hand" quat="0 1 0 1">
      <inertial mass="3" pos="0 0 0.09" diaginertia="0.0138 0.0138 0.00744"/>
      <site name="attachment_site" pos="0 0 0" group="4"/>
      <geom class="plastic_visual" mesh="forearm_0" material="gray"/>
      <geom class="plastic_visual" mesh="forearm_1"/>
      <geom class="plastic_collision" type="mesh" mesh="forearm_collision"/>
      <geom class="plastic_collision" size="0.035 0.035 0.035" pos="0.01 0.0 0.181" quat="0.380188 0.924909 0 0"
        type="box"/>
      <body name="rh_wrist" pos="0.01 0 0.21301" quat="1 0 0 1">
        <inertial mass="0.1" pos="0 0 0.029" quat="0.5 0.5 0.5 0.5" diaginertia="6.4e-05 4.38e-05 3.5e-05"/>
        <joint class="wrist_y" name="rh_WRJ2"/>
        <geom class="plastic_visual" mesh="wrist" material="metallic"/>
        <geom size="0.0135 0.015" quat="0.499998 0.5 0.5 -0.500002" type="cylinder" class="plastic_collision"/>
        <geom size="0.011 0.005" pos="-0.026 0 0.034" quat="1 0 1 0" type="cylinder" class="plastic_collision"/>
        <geom size="0.011 0.005" pos="0.031 0 0.034" quat="1 0 1 0" type="cylinder" class="plastic_collision"/>
        <geom size="0.0135 0.009 0.005" pos="-0.021 0 0.011" quat="0.923879 0 0.382684 0" type="box"
          class="plastic_collision"/>
        <geom size="0.0135 0.009 0.005" pos="0.026 0 0.01" quat="0.923879 0 -0.382684 0" type="box"
          class="plastic_collision"/>
        <body name="rh_palm" pos="0 0 0.034">
          <inertial mass="0.3" pos="0 0 0.035" quat="1 0 0 1" diaginertia="0.0005287 0.0003581 0.000191"/>
          <joint class="wrist_x" name="rh_WRJ1"/>
          <site name="grasp_site" pos="0 -.035 0.09" group="4"/>
          <geom class="plastic_visual" mesh="palm"/>
          <geom size="0.031 0.0035 0.049" pos="0.011 0.0085 0.038" type="box" class="plastic_collision"/>
          <geom size="0.018 0.0085 0.049" pos="-0.002 -0.0035 0.038" type="box" class="plastic_collision"/>
          <geom size="0.013 0.0085 0.005" pos="0.029 -0.0035 0.082" type="box" class="plastic_collision"/>
          <geom size="0.013 0.007 0.009" pos="0.0265 -0.001 0.07" quat="0.987241 0.0990545 0.0124467 0.124052"
            type="box" class="plastic_collision"/>
          <geom size="0.0105 0.0135 0.012" pos="0.0315 -0.0085 0.001" type="box" class="plastic_collision"/>
          <geom size="0.011 0.0025 0.015" pos="0.0125 -0.015 0.004" quat="0.971338 0 0 -0.237703" type="box"
            class="plastic_collision"/>
          <geom size="0.009 0.012 0.002" pos="0.011 0 0.089" type="box" class="plastic_collision"/>
          <geom size="0.01 0.012 0.02" pos="-0.03 0 0.009" type="box" class="plastic_collision"/>
          <body name="rh_ffknuckle" pos="0.033 0 0.095">
            <inertial mass="0.008" pos="0 0 0" quat="0.5 0.5 -0.5 0.5" diaginertia="3.2e-07 2.6e-07 2.6e-07"/>
            <joint name="rh_FFJ4" class="knuckle"/>
            <geom pos="0 0 0.0005" class="plastic_visual" mesh="f_knuckle" material="metallic"/>
            <geom size="0.009 0.009" quat="1 0 1 0" type="cylinder" class="plastic_collision"/>
            <body name="rh_ffproximal">
              <inertial mass="0.03" pos="0 0 0.0225" quat="1 0 0 1" diaginertia="1e-05 9.8e-06 1.8e-06"/>
              <joint name="rh_FFJ3" class="proximal"/>
              <geom class="plastic_visual" mesh="f_proximal"/>
              <geom size="0.009 0.02" pos="0 0 0.025" type="capsule" class="plastic_collision"/>
              <body name="rh_ffmiddle" pos="0 0 0.045">
                <inertial mass="0.017" pos="0 0 0.0125" quat="1 0 0 1" diaginertia="2.7e-06 2.6e-06 8.7e-07"/>
                <joint name="rh_FFJ2" class="middle_distal"/>
                <geom class="plastic_visual" mesh="f_middle"/>
                <geom size="0.009 0.0125" pos="0 0 0.0125" type="capsule" class="plastic_collision"/>
                <body name="rh_ffdistal" pos="0 0 0.025">
                  <inertial mass="0.013" pos="0 0 0.0130769" quat="1 0 0 1"
                    diaginertia="1.28092e-06 1.12092e-06 5.3e-07"/>
                  <joint name="rh_FFJ1" class="middle_distal"/>
                  <geom class="plastic_visual" mesh="f_distal_pst"/>
                  <geom class="plastic_collision" type="mesh" mesh="f_distal_pst"/>
                </body>
              </body>
            </body>
          </body>
          <body name="rh_mfknuckle" pos="0.011 0 0.099">
            <inertial mass="0.008" pos="0 0 0" quat="0.5 0.5 -0.5 0.5" diaginertia="3.2e-07 2.6e-07 2.6e-07"/>
            <joint name="rh_MFJ4" class="knuckle"/>
            <geom pos="0 0 0.0005" class="plastic_visual" mesh="f_knuckle" material="metallic"/>
            <geom size="0.009 0.009" quat="1 0 1 0" type="cylinder" class="plastic_collision"/>
            <body name="rh_mfproximal">
              <inertial mass="0.03" pos="0 0 0.0225" quat="1 0 0 1" diaginertia="1e-05 9.8e-06 1.8e-06"/>
              <joint name="rh_MFJ3" class="proximal"/>
              <geom class="plastic_visual" mesh="f_proximal"/>
              <geom size="0.009 0.02" pos="0 0 0.025" type="capsule" class="plastic_collision"/>
              <body name="rh_mfmiddle" pos="0 0 0.045">
                <inertial mass="0.017" pos="0 0 0.0125" quat="1 0 0 1" diaginertia="2.7e-06 2.6e-06 8.7e-07"/>
                <joint name="rh_MFJ2" class="middle_distal"/>
                <geom class="plastic_visual" mesh="f_middle"/>
                <geom size="0.009 0.0125" pos="0 0 0.0125" type="capsule" class="plastic_collision"/>
                <body name="rh_mfdistal" pos="0 0 0.025">
                  <inertial mass="0.013" pos="0 0 0.0130769" quat="1 0 0 1"
                    diaginertia="1.28092e-06 1.12092e-06 5.3e-07"/>
                  <joint name="rh_MFJ1" class="middle_distal"/>
                  <geom class="plastic_visual" mesh="f_distal_pst"/>
                  <geom class="plastic_collision" type="mesh" mesh="f_distal_pst"/>
                </body>
              </body>
            </body>
          </body>
          <body name="rh_rfknuckle" pos="-0.011 0 0.095">
            <inertial mass="0.008" pos="0 0 0" quat="0.5 0.5 -0.5 0.5" diaginertia="3.2e-07 2.6e-07 2.6e-07"/>
            <joint name="rh_RFJ4" class="knuckle" axis="0 1 0"/>
            <geom pos="0 0 0.0005" class="plastic_visual" mesh="f_knuckle" material="metallic"/>
            <geom size="0.009 0.009" quat="1 0 1 0" type="cylinder" class="plastic_collision"/>
            <body name="rh_rfproximal">
              <inertial mass="0.03" pos="0 0 0.0225" quat="1 0 0 1" diaginertia="1e-05 9.8e-06 1.8e-06"/>
              <joint name="rh_RFJ3" class="proximal"/>
              <geom class="plastic_visual" mesh="f_proximal"/>
              <geom size="0.009 0.02" pos="0 0 0.025" type="capsule" class="plastic_collision"/>
              <body name="rh_rfmiddle" pos="0 0 0.045">
                <inertial mass="0.017" pos="0 0 0.0125" quat="1 0 0 1" diaginertia="2.7e-06 2.6e-06 8.7e-07"/>
                <joint name="rh_RFJ2" class="middle_distal"/>
                <geom class="plastic_visual" mesh="f_middle"/>
                <geom size="0.009 0.0125" pos="0 0 0.0125" type="capsule" class="plastic_collision"/>
                <body name="rh_rfdistal" pos="0 0 0.025">
                  <inertial mass="0.013" pos="0 0 0.0130769" quat="1 0 0 1"
                    diaginertia="1.28092e-06 1.12092e-06 5.3e-07"/>
                  <joint name="rh_RFJ1" class="middle_distal"/>
                  <geom class="plastic_visual" mesh="f_distal_pst"/>
                  <geom class="plastic_collision" type="mesh" mesh="f_distal_pst"/>
                </body>
              </body>
            </body>
          </body>
          <body name="rh_lfmetacarpal" pos="-0.033 0 0.02071">
            <inertial mass="0.03" pos="0 0 0.04" quat="1 0 0 1" diaginertia="1.638e-05 1.45e-05 4.272e-06"/>
            <joint name="rh_LFJ5" class="metacarpal"/>
            <geom class="plastic_visual" mesh="lf_metacarpal"/>
            <geom size="0.011 0.012 0.025" pos="0.002 0 0.033" type="box" class="plastic_collision"/>
            <body name="rh_lfknuckle" pos="0 0 0.06579">
              <inertial mass="0.008" pos="0 0 0" quat="0.5 0.5 -0.5 0.5" diaginertia="3.2e-07 2.6e-07 2.6e-07"/>
              <joint name="rh_LFJ4" class="knuckle" axis="0 1 0"/>
              <geom pos="0 0 0.0005" class="plastic_visual" mesh="f_knuckle" material="metallic"/>
              <geom size="0.009 0.009" quat="1 0 1 0" type="cylinder" class="plastic_collision"/>
              <body name="rh_lfproximal">
                <inertial mass="0.03" pos="0 0 0.0225" quat="1 0 0 1" diaginertia="1e-05 9.8e-06 1.8e-06"/>
                <joint name="rh_LFJ3" class="proximal"/>
                <geom class="plastic_visual" mesh="f_proximal"/>
                <geom size="0.009 0.02" pos="0 0 0.025" type="capsule" class="plastic_collision"/>
                <body name="rh_lfmiddle" pos="0 0 0.045">
                  <inertial mass="0.017" pos="0 0 0.0125" quat="1 0 0 1" diaginertia="2.7e-06 2.6e-06 8.7e-07"/>
                  <joint name="rh_LFJ2" class="middle_distal"/>
                  <geom class="plastic_visual" mesh="f_middle"/>
                  <geom size="0.009 0.0125" pos="0 0 0.0125" type="capsule" class="plastic_collision"/>
                  <body name="rh_lfdistal" pos="0 0 0.025">
                    <inertial mass="0.013" pos="0 0 0.0130769" quat="1 0 0 1"
                      diaginertia="1.28092e-06 1.12092e-06 5.3e-07"/>
                    <joint name="rh_LFJ1" class="middle_distal"/>
                    <geom class="plastic_visual" mesh="f_distal_pst"/>
                    <geom class="plastic_collision" type="mesh" mesh="f_distal_pst"/>
                  </body>
                </body>
              </body>
            </body>
          </body>
          <body name="rh_thbase" pos="0.034 -0.00858 0.029" quat="0.92388 0 0.382683 0">
            <inertial mass="0.01" pos="0 0 0" diaginertia="1.6e-07 1.6e-07 1.6e-07"/>
            <joint name="rh_THJ5" class="thbase"/>
            <geom class="plastic_collision" size="0.013"/>
            <body name="rh_thproximal">
              <inertial mass="0.04" pos="0 0 0.019" diaginertia="1.36e-05 1.36e-05 3.13e-06"/>
              <joint name="rh_THJ4" class="thproximal"/>
              <geom class="plastic_visual" mesh="th_proximal"/>
              <geom class="plastic_collision" size="0.0105 0.009" pos="0 0 0.02" type="capsule"/>
              <body name="rh_thhub" pos="0 0 0.038">
                <inertial mass="0.005" pos="0 0 0" diaginertia="1e-06 1e-06 3e-07"/>
                <joint name="rh_THJ3" class="thhub"/>
                <geom size="0.011" class="plastic_collision"/>
                <body name="rh_thmiddle">
                  <inertial mass="0.02" pos="0 0 0.016" diaginertia="5.1e-06 5.1e-06 1.21e-06"/>
                  <joint name="rh_THJ2" class="thmiddle"/>
                  <geom class="plastic_visual" mesh="th_middle"/>
                  <geom size="0.009 0.009" pos="0 0 0.012" type="capsule" class="plastic_collision"/>
                  <geom size="0.01" pos="0 0 0.03" class="plastic_collision"/>
                  <body name="rh_thdistal" pos="0 0 0.032" quat="1 0 0 -1">
                    <inertial mass="0.017" pos="0 0 0.0145588" quat="1 0 0 1"
                      diaginertia="2.37794e-06 2.27794e-06 1e-06"/>
                    <joint name="rh_THJ1" class="thdistal"/>
                    <geom class="plastic_visual" mesh="th_distal_pst"/>
                    <geom class="plastic_collision" type="mesh" mesh="th_distal_pst"/>
                  </body>
                </body>
              </body>
            </body>
          </body>
        </body>
      </body>
    </body>
  </worldbody>

  <contact>
    <exclude body1="rh_wrist" body2="rh_forearm"/>
    <exclude body1="rh_thproximal" body2="rh_thmiddle"/>
  </contact>

  <tendon>
    <fixed name="rh_FFJ0">
      <joint joint="rh_FFJ2" coef="1"/>
      <joint joint="rh_FFJ1" coef="1"/>
    </fixed>
    <fixed name="rh_MFJ0">
      <joint joint="rh_MFJ2" coef="1"/>
      <joint joint="rh_MFJ1" coef="1"/>
    </fixed>
    <fixed name="rh_RFJ0">
      <joint joint="rh_RFJ2" coef="1"/>
      <joint joint="rh_RFJ1" coef="1"/>
    </fixed>
    <fixed name="rh_LFJ0">
      <joint joint="rh_LFJ2" coef="1"/>
      <joint joint="rh_LFJ1" coef="1"/>
    </fixed>
  </tendon>

  <actuator>
    <position name="rh_A_WRJ2" joint="rh_WRJ2" class="wrist_y"/>
    <position name="rh_A_WRJ1" joint="rh_WRJ1" class="wrist_x"/>
    <position name="rh_A_THJ5" joint="rh_THJ5" class="thbase"/>
    <position name="rh_A_THJ4" joint="rh_THJ4" class="thproximal"/>
    <position name="rh_A_THJ3" joint="rh_THJ3" class="thhub"/>
    <position name="rh_A_THJ2" joint="rh_THJ2" class="thmiddle"/>
    <position name="rh_A_THJ1" joint="rh_THJ1" class="thdistal"/>
    <position name="rh_A_FFJ4" joint="rh_FFJ4" class="knuckle"/>
    <position name="rh_A_FFJ3" joint="rh_FFJ3" class="proximal"/>
    <position name="rh_A_FFJ0" tendon="rh_FFJ0" class="middle_distal"/>
    <position name="rh_A_MFJ4" joint="rh_MFJ4" class="knuckle"/>
    <position name="rh_A_MFJ3" joint="rh_MFJ3" class="proximal"/>
    <position name="rh_A_MFJ0" tendon="rh_MFJ0" class="middle_distal"/>
    <position name="rh_A_RFJ4" joint="rh_RFJ4" class="knuckle"/>
    <position name="rh_A_RFJ3" joint="rh_RFJ3" class="proximal"/>
    <position name="rh_A_RFJ0" tendon="rh_RFJ0" class="middle_distal"/>
    <position name="rh_A_LFJ5" joint="rh_LFJ5" class="metacarpal"/>
    <position name="rh_A_LFJ4" joint="rh_LFJ4" class="knuckle"/>
    <position name="rh_A_LFJ3" joint="rh_LFJ3" class="proximal"/>
    <position name="rh_A_LFJ0" tendon="rh_LFJ0" class="middle_distal"/>
  </actuator>

  <keyframe>
    <key name="scissors" qpos="0 0 -0.2094 0 0 0 0.002094 0 0 0 0 1.484 1.484 1.484 0 0 1.484 1.484 1.484 0 0 0 0.6981 0"/>
    <key name="rock" qpos="0 0 0 1.484 1.484 1.484 0 1.484 1.484 1.484 0 1.484 1.484 1.484 0 0 1.484 1.484 1.484 0.1745 1.239 0.08727 0.6981 0.6981"/>
    <key name="paper" qpos="0 0 0 0 0 0 0 0 0 0 0 0 0 0 0 0 0 0 0 0 0 0 0.6981 0"/>
    <key name="open hand" qpos="0 0 0 0 0 0 0 0 0 0 0 0 0 0 0 0 0 0 0 0 0 0 0 0"/>
    <key name="close hand" qpos="0 0 0 1.5708 1.5708 1.5708 0 1.5708 1.5708 1.5708 0 1.5708 1.5708 1.5708 0 0 1.5708 1.5708 1.5708 0.17 1.2 0 0.61 0.52"/>
    <key name="point" qpos="0.00428 -0.06155 -0.06356 0.001284 0.03357 0 0.007048 1.522 1.5708 1.422 0.01667 1.558 1.5708 0.6359 0.01429 -0.005259 1.484 1.5708 1.47 0.1813 1.091 0.001119 0.6403 0.5175"/>
    <key name="two finger pinch" qpos="0.0188 -0.2686 -0.3013 0.9774 1.045 0.1665 0.1255 0.165 0.3459 0.0005741 -0.1349 0.4096 0.04252 0.03161 0.1938 -0.2039 0.05253 0.4297 0.009526 0.03082 1.08 0.1604 0.5839 0.3069"/>
    <key name="three finger pinch" qpos="-0.01977 -0.5255 -0.3464 1.253 0.7836 0 0.01103 1.475 0.6181 0.0155 -0.2083 0.3328 0.07129 0.02873 0.1829 -0.2676 0.05465 0.3892 0.008468 0.07708 1.21 0.2023 0.6614 0.0102"/>
    <key name="parallel extension" qpos="0.02402 0.2099 -0.006586 1.39 0.3971 0.004978 -0.006607 1.497 0.2583 0.005741 0.1438 1.536 0 0.01772 0.07822 0.02017 1.404 0 0.02382 0.1293 1.21 0.1619 0.4329 0.1276"/>
    <key name="grasp sphere" qpos="0.002807 -0.7097 -0.352 0.8337 1.32 0.1101 -0.07213 0.829 1.309 0.02985 -0.1276 0.986 1.101 0.05124 0.1683 -0.3401 0.7487 1.176 0.0307 -0.0657 1.213 0.1983 0.6407 0.4141"/>
    <key name="pre grasp" qpos="-0.03896 -0.5694 -0.3497 0.1074 0.1424 0 -0.05406 -0.07509 0.4658 0.01033 -0.1062 0.2738 0.001251 0.02586 0.1551 -0.3593 0.1445 0 0 -0.1413 0.8383 0.199 0.4945 0.1291"/>
    <key name="grasp soft" qpos="-0.01386 -0.5706 -0.3126 1.013 0.5084 0.002212 -0.139 0.6854 0.9554 0.01895 0.1659 1.13 0.04252 0.02969 0.3183 -0.2968 0.8024 0.8261 0.01958 -0.04934 0.92 0.1932 0.5457 0.1011"/>
    <key name="grasp hard" qpos="-0.06713 -0.5377 -0.3099 1.128 0.5067 0.001659 -0.1352 0.8652 0.93 0.01263 0.1724 1.165 0.2726 0.034 0.3116 -0.354 0.9553 0.7928 0.01958 0.05755 1.182 0.1947 0.5578 0.2482"/>
  </keyframe>
</mujoco>
